<?xml version='1.0'?>
<sdf version='1.4'>



  <model name="mobile_base">
    <link name='chassis'>
      <pose>0 0 .25 0 0 0</pose>

      <inertial>
        <mass>20.0</mass>
        <pose>-0.1 0 -0.1 0 0 0</pose>
        <inertia>
          <ixx>0.5</ixx>
          <iyy>1.0</iyy>
          <izz>0.1</izz>
        </inertia>
      </inertial>

      <collision name='collision'>
        <geometry>
          <box>
            <size>2 1 0.3</size>
          </box>
        </geometry>
      </collision>

      <visual name='visual'>
        <geometry>
          <box>
            <size>2 1 0.3</size>
          </box>
        </geometry>
      </visual>

      <collision name='caster_collision'>
        <pose>-0.8 0 -0.125 0 0 0</pose>
        <geometry>
          <sphere>
            <radius>.125</radius>
          </sphere>
        </geometry>

        <surface>
          <friction>
            <ode>
              <mu>0</mu>
              <mu2>0</mu2>
            </ode>
          </friction>
        </surface>
      </collision>

      <visual name='caster_visual'>
        <pose>-0.8 0 -0.125 0 0 0</pose>
        <geometry>
          <sphere>
            <radius>.125</radius>
          </sphere>
        </geometry>
      </visual>
    </link>
    <link name="left_wheel">
      <pose>0.8 0.6 0.125 0 1.5707 1.5707</pose>
      <collision name="collision">
        <geometry>
          <cylinder>
            <radius>.125</radius>
            <length>.05</length>
          </cylinder>
        </geometry>
      </collision>
      <visual name="visual">
        <geometry>
          <cylinder>
            <radius>.125</radius>
            <length>.05</length>
          </cylinder>
        </geometry>
      </visual>
    </link>

    <link name="right_wheel">
      <pose>0.8 -0.6 0.125 0 1.5707 1.5707</pose>
      <collision name="collision">
        <geometry>
          <cylinder>
            <radius>.125</radius>
            <length>.05</length>
          </cylinder>
        </geometry>
      </collision>
      <visual name="visual">
        <geometry>
          <cylinder>
            <radius>.125</radius>
            <length>.05</length>
          </cylinder>
        </geometry>
      </visual>
    </link>

    <joint type="revolute" name="left_wheel_hinge">
      <pose>0 0 -0.03 0 0 0</pose>
      <child>left_wheel</child>
      <parent>chassis</parent>
      <axis>
        <use_parent_model_frame>true</use_parent_model_frame>
        <xyz>0 1 0</xyz>
      </axis>
    </joint>

    <joint type="revolute" name="right_wheel_hinge">
      <pose>0 0 0.03 0 0 0</pose>
      <child>right_wheel</child>
      <parent>chassis</parent>
      <axis>
        <use_parent_model_frame>true</use_parent_model_frame>
        <xyz>0 1 0</xyz>
      </axis>
    </joint>

  

  <!-- <model name="camera"> -->
<!--
    <link name="link">
      <pose>1.2 0 1.15 0 0 0</pose>
      <inertial>
        <mass>0.1</mass>
        <inertia>
          <ixx>0.000166667</ixx>
          <iyy>0.000166667</iyy>
          <izz>0.000166667</izz>
        </inertia>
      </inertial>
      <collision name="collision">
        <geometry>
          <box>
            <size>0.1 0.1 0.1</size>
          </box>
        </geometry>
      </collision>
      <visual name="visual">
        <geometry>
          <box>
            <size>0.1 0.1 0.1</size>
          </box>
        </geometry>
      </visual>
      <sensor name="camera" type="camera">
        <camera>
          <horizontal_fov>1.047</horizontal_fov>
          <image>
            <width>320</width>
            <height>240</height>
          </image>
          <clip>
            <near>0.1</near>
            <far>100</far>
          </clip>
        </camera>

        <plugin name="camera_controller" filename="libgazebo_ros_camera.so">
          <alwaysOn>true</alwaysOn>
          <updateRate>0.0</updateRate>
          <cameraName>my_robot_camera/camera1</cameraName>
          <imageTopicName>image_raw</imageTopicName>
          <cameraInfoTopicName>camera_info</cameraInfoTopicName>
          <frameName>camera_link</frameName>
          <hackBaseline>0.07</hackBaseline>
        </plugin>



      </sensor>
    </link>


    <joint name="camera_joint" type="fixed">
      <child>camera::link</child>
      <parent>simple_gripper::riser</parent>
    </joint> -->






  <!-- </model> -->




<!--    <plugin name="differential_drive_controller" filename="libgazebo_ros_diff_drive.so">


  <alwaysOn>true</alwaysOn>
  <updateRate>100</updateRate>
  <leftJoint>left_wheel_hinge</leftJoint>
  <rightJoint>right_wheel_hinge</rightJoint>
  <wheelSeparation>0.39</wheelSeparation>
  <wheelDiameter>0.15</wheelDiameter>
  <torque>5</torque>
  <commandTopic>cmd_vel</commandTopic>
   <odometryTopic>odom</odometryTopic>
   <odometryFrame>odom</odometryFrame>
  <robotBaseFrame>chassis</robotBaseFrame>


    </plugin> -->


</model>

</sdf>


<!--
  <model name="my_robot">

    <static>false</static>

    <link name='chassis'>
      <pose>0 0 .1 0 0 0</pose>

      <collision name='collision'>
        <pose>0 0 0.05 0 0 0</pose>
        <geometry>
          <mesh>
            <uri>model://pioneer2dx/meshes/chassis.dae</uri>
            <scale>0.9 0.5 0.5</scale>
          </mesh>
        </geometry>
      </collision>

      <visual name='visual'>
        <pose>0 0 0.05 0 0 0</pose>
        <geometry>
          <mesh>
            <uri>model://pioneer2dx/meshes/chassis.dae</uri>
            <scale>0.9 0.5 0.5</scale>
          </mesh>
        </geometry>
      </visual>

      <collision name='caster_collision'>
        <pose>-0.15 0 -0.05 0 0 0</pose>
        <geometry>
          <sphere>
            <radius>.05</radius>
          </sphere>
        </geometry>

        <surface>
          <friction>
            <ode>
              <mu>0</mu>
              <mu2>0</mu2>
              <slip1>1.0</slip1>
              <slip2>1.0</slip2>
            </ode>
          </friction>
        </surface>
      </collision>

      <visual name='caster_visual'>
        <pose>-0.15 0 -0.05 0 0 0</pose>
        <geometry>
          <sphere>
            <radius>.05</radius>
          </sphere>
        </geometry>
      </visual>
    </link>
    <link name="left_wheel">
      <pose>0.1 0.13 0.1 0 1.5707 1.5707</pose>
      <collision name="collision">
        <geometry>
          <cylinder>
            <radius>.1</radius>
            <length>.05</length>
          </cylinder>
        </geometry>
      </collision>
      <visual name="visual">
        <geometry>
          <cylinder>
            <radius>.1</radius>
            <length>.05</length>
          </cylinder>
        </geometry>
      </visual>
    </link>

    <link name="right_wheel">
      <pose>0.1 -0.13 0.1 0 1.5707 1.5707</pose>
      <collision name="collision">
        <geometry>
          <cylinder>
            <radius>.1</radius>
            <length>.05</length>
          </cylinder>
        </geometry>
      </collision>
      <visual name="visual">
        <geometry>
          <cylinder>
            <radius>.1</radius>
            <length>.05</length>
          </cylinder>
        </geometry>
      </visual>
    </link>

    <joint type="revolute" name="left_wheel_hinge">
      <pose>0 0 -0.03 0 0 0</pose>
      <child>left_wheel</child>
      <parent>chassis</parent>
      <axis>
        <xyz>0 1 0</xyz>
      </axis>
    </joint>

    <joint type="revolute" name="right_wheel_hinge">
      <pose>0 0 0.03 0 0 0</pose>
      <child>right_wheel</child>
      <parent>chassis</parent>
      <axis>
        <xyz>0 1 0</xyz>
      </axis>
    </joint>

   <include>
      <uri>model://hokuyo</uri>
      <pose>-0.4 0 0.2 0 0 0</pose>
    </include>
    <joint name="hokuyo_joint" type="fixed">
      <child>hokuyo::link</child>
      <parent>chassis</parent>
    </joint>


 
  <model name="distorted_camera">
    <link name="link">
      <pose>-0.05 0.05 0.5 0 0 0</pose>
      <inertial>
        <mass>0.1</mass>
        <inertia>
          <ixx>0.000166667</ixx>
          <iyy>0.000166667</iyy>
          <izz>0.000166667</izz>
        </inertia>
      </inertial>
      <collision name="collision">
        <geometry>
          <box>
            <size>0.1 0.1 0.1</size>
          </box>
        </geometry>
      </collision>
      <visual name="visual">
        <geometry>
          <box>
            <size>0.1 0.1 0.1</size>
          </box>
        </geometry>
      </visual>
      <sensor name="camera" type="camera">
        <camera>
          <horizontal_fov>1.047</horizontal_fov>
          <image>
            <width>320</width>
            <height>240</height>
          </image>
          <clip>
            <near>0.1</near>
            <far>100</far>
          </clip>
        </camera>

        <plugin name="camera_controller" filename="libgazebo_ros_camera.so">
          <alwaysOn>true</alwaysOn>
          <updateRate>0.0</updateRate>
          <cameraName>my_robot_camera/camera1</cameraName>
          <imageTopicName>image_raw</imageTopicName>
          <cameraInfoTopicName>camera_info</cameraInfoTopicName>
          <frameName>camera_link</frameName>
          <hackBaseline>0.07</hackBaseline>
        </plugin>



      </sensor>
    </link>
  </model>






  </model>
</sdf> -->

